Workbook

Sheet Население
C1: Факультет: | I1: Команда:
A4: Министр по делам населения (Population) | C4: Лист решений
A6: Переменная | B6: Что описывает | C6: Старт. значение | D6: Периоды | M6: Целевое значение
C7: 0-4 | D7: 5-9 | E7: 10-14 | F7: 15-19 | G7: 20-24 | H7: 25-29 | I7: 30-34 | J7: 35-39 | K7: 40-44 | L7: 45-49
A8: Текущая ситуация
A9: P1 | B9: Численность населения | C9: 200 | D9: =ROUND(C9+C9/1000*D18*5-C9/1000*D15*5,-1) -> 220 | M9: 500
A10: P2 | B10: Всего продовольствия от импорта и пр-ва (п.п.) | C10: 3300 | D10: ='Сельхоз и ОС'!D23+'Сельхоз и ОС'!D21 -> 2890 | M10: 12500
A11: P3 | B11: Всего товаров от импорта и пр-ва (п.п.) | C11: 3500 | D11: =Промышленность!D24+Промышленность!D22 -> 6758.8182 | M11: 68600
A13: Информация к сведению
A14: P4 | B14: Продовольствие на душу населения в год (п.п.) | C14: 2 | D14: =C21/(C9*5) -> 2 | M14: 5
A15: P5 | B15: Уровень смертности, чел./1000 чел. в год (п.п.) | C15: 18 | D15: 18.2 | M15: 10
A16: P6 | B16: Товары на душу населения в год (п.п.) | C16: 2 | D16: =C26/(C9*5) -> 2 | M16: 15
A17: P7 | B17: Услуги на душу населения в год (п.п.) | C17: 2.25 | D17: =Промышленность!D14/Население!C9 -> 4 | M17: 18
A18: P8 | B18: Уровень рождаемости, чел./1000 чел. в год (п.п.) | C18: 41 | D18: 39.2 | M18: 10
A20: Решение №1: | B20: Распределить все продовольствие
A21: P9 | B21: Продовольствие для населения (т.п.) | C21: 2000
A22: P10 | B22: Продовольствие на экспорт (т.п.) | C22: ='Торговля и финансы'!C24 -> 1300
A23: Всего: | B23: P9 + P10 = P2 | C23: =IF(C21+C22=C10, C10, "проверь!") -> 3300
A25: Решение №2: | B25: Распределить все товары
A26: P11 | B26: Товары для населения (т.п.) | C26: 2000
A27: P12 | B27: Товары для капиталовложения (т.п.) | C27: 1500
A28: P13 | B28: Товары на экспорт (т.п.) | C28: ='Торговля и финансы'!C23 -> 0
A29: Всего: | B29: P11 + P12 + P13 = P3 | C29: =IF(C26+C27+C28=C11, C11, "проверь!") -> 3500
A35: Информация для разработчика | C35: п.п. | D35: прошлый период | G35: Индекс пред - переменная из предыдущего столбца (левее)
C36: т.п. | D36: текущий период | G36: Индекс тек - переменная из текущего столбца
A37: Формулы и соотношения
A39: Переменная | B39: Что описывает | C39: Как рассчитывается | H39: Комментарий
A40: P1 | B40: Численность населения | C40: = P1пред + P1пред/1000*P8тек*5 - P1пред/1000*P5тек*5 | H40: Округляется до десятков и остается постоянной в течение всего периода. Сначала рассчитываются текущие уровни рождаемости P8 и смертности P5, потом через них и предыдущую численность P1пред населения рассчитывается текущая численность населения P1
A41: P2 | B41: Всего продовольствия от импорта и пр-ва (п.п.) | C41: = F13тек + F11тек | H41: Сначала рассчитываются текущие импорт продовольствия F13 и производство продовольствия F11, потом через них текущее значение P2
A42: P3 | B42: Всего товаров от импорта и пр-ва (п.п.) | C42: = G14тек + G12тек | H42: Сначала рассчитываются текущие импорт товаров G14 и производство товаров G12, потом через них текущее значение P3
A43: P4 | B43: Продовольствие на душу населения в год | C43: = P9пред / (P1пред* 5) | H43: Стартовое значение 2 задано в явном виде, все последующие рассчитываются с учетом принятых решений P9 Министра по делам населения
A44: P5 | B44: Уровень смертности, чел./1000 чел. в год (п.п.) | C44: = (линейной интерполяцией по Графику P-3 как функция от P4тек) * (линейной интерполяцией по Графику P-4 как функция от F7тек) * 1000 | H44: Стартовое значение 18 уже рассчитано по этой методике по стартовым значениям P4 и F7
A45: P6 | B45: Товары на душу населения в год (п.п.) | C45: = P11пред / (P1пред* 5) | H45: Стартовое значение 2 задано в явном виде, все последующие рассчитываются с учетом принятых решений P11 Министра по делам населения
A46: P7 | B46: Услуги на душу населения в год (п.п.) | C46: = G6тек / (P1пред) | H46: Стартовое значение 2,25 уже рассчитано по этой методике по стартовым значениям G6 и P1
A47: P8 | B47: Уровень рождаемости, чел./1000 чел. в год (п.п.) | C47: = (линейной интерполяцией по Графику P-1 как функция от P6тек) * (линейной интерполяцией по Графику P-2 как функция от P7тек) * 1000 | H47: Стартовое значение 41 уже рассчитано по этой методике по стартовым значениям P6 и P7
A49: Проверка выполнения равенства при заполнении листа решений
B50: P9 + P10 = P2 | H50: Распределяемое на P9 и P10 продовольствие должно в сумме равняться P2
B51: P11 + P12 + P13 = P3 | H51: Распределяемые на P11, P12 и P13 товары должны в сумме равняться P3
A53: Проверка корректности численных значений
B54: P4 ≤ 5 | C54: Максимальное количество продовольствия на душу населения в год (расчетное значение P4) в игре составляет 5. Принятое игроками Решение №1 о распределении продовольствия P9 для всего населения на период (т.е. на 5 лет) должно соответствовать этому правилу.
...

Sheet Энергетика
C1: Факультет: | I1: Команда:
A4: Министр энергетики (Energy production) | C4: Лист решений
A6: Переменная | B6: Что описывает | C6: Старт. значение | D6: Периоды | M6: Целевое значение
C7: 0-4 | D7: 5-9 | E7: 10-14 | F7: 15-19 | G7: 20-24 | H7: 25-29 | I7: 30-34 | J7: 35-39 | K7: 40-44 | L7: 45-49
A8: Текущая ситуация
A9: E1 | B9: Выбытие капитала для пр-ва энергии (в конце периода) | C9: 160 | D9: =D11/5 -> 228 | M9: 1200
A10: E2 | B10: Новый капитал для пр-ва энергии (т.п.) | C10: 640 | D10: =D11*4/5 -> 912 | M10: 4800
A11: E3 | B11: Основной капитал для пр-ва энергии (т.п.) | C11: =C9+C10 -> 800 | D11: =C11-C9+C44 -> 1140 | M11: 6000
A12: E4 | B12: Выбытие капитала энергосбережения (в конце периода) | C12: 0 | D12: =D14/5 -> 60 | M12: 840
A13: E5 | B13: Новый капитал энергосбережения (т.п.) | C13: 0 | D13: =D14*4/5 -> 240 | M13: 3360
A14: E6 | B14: Основной капитал энергосбережения (т.п.) | C14: =C12+C13 -> 0 | D14: =C14-C12+C45 -> 300 | M14: 4200
A15: E7 | B15: Всего энергоресурсов (т.п.) от пр-ва, импорта и резерва | C15: 15000 | D15: =D27+D29+C34 -> 18850 | M15: 56000
A17: Информация к сведению
A18: E8 | B18: Энергоресурсы на единицу потребляемых товаров | C18: 0.2 | D18: 0.2 | E18: 0.2 | F18: 0.2 | G18: 0.2 | H18: 0.2 | I18: 0.2 | J18: 0.2 | K18: 0.2 | L18: 0.2 | M18: 0.2
A19: E9 | B19: Энергоресурсы для населения (п.п.) | C19: 400 | D19: =Население!C26/5 -> 400 | M19: 7500
A20: E10 | B20: Коэффициент потребления ресурсов | C20: 1 | D20: 0.64 | M20: 0.4
A21: E11 | B21: Энергоресурсы на единицу с/х капитала (п.п.) | C21: 12.5 | D21: =D20*2.5*5 -> 8 | M21: 5
A22: E12 | B22: Потребность в энергии для сельского хозяйства (п.п.) | C22: 10000 | D22: =D21*'Сельхоз и ОС'!D11 -> 6720 | M22: 12500
A23: E13 | B23: Энергоресурсы на единицу пром. капитала (п.п) | C23: 20 | D23: =D20*4*5 -> 12.8 | M23: 8
A24: E14 | B24: Потребность в энергии для пр-ва товаров (п.п.) | C24: 6000 | D24: =D23*Промышленность!D11 -> 4352 | M24: 36000
A25: E15 | B25: Потребность в энергии для с/х и пром. пр-ва (п.п.) | C25: =C22+C24 -> 16000 | D25: =D22+D24 -> 11072 | M25: 48500
A26: E16 | B26: Генерация энергии на единицу капитала в энергетике (т.п.) | C26: 17.5 | D26: =D27/D11 -> 15.657895 | M26: 5
A27: E17 | B27: Пр-во энергоресурсов (т.п.) | C27: 14000 | D27: 17850 | M27: 30000
A28: E18 | B28: Энергоресурсы на экспорт (п.п.) | C28: 0 | D28: =C33 -> 0 | M28: 0
A29: E19 | B29: Импорт энергоресурсов (п.п.) | C29: 1000 | D29: ='Торговля и финансы'!C34/'Торговля и финансы'!C16 -> 1000 | M29: 26000
A31: Решение №3: | B31: Распределить энергоресурсы по направлениям
A32: E20 | B32: Энергоресурсы для населения (1/5 потребл. товаров) | C32: 400
A33: E21 | B33: Энергоресурсы на экспорт | C33: ='Торговля и финансы'!C22 -> 0
A34: E22 | B34: Энергоресурсы в резерв | C34: 0
A35: E23 | B35: Энергоресурсы для пр-ва товаров и продовольствия | C35: 14600
A36: Всего: | B36: E20 + E21 + E22 + E23 = E7 | C36: =IF(C32+C33+C34+C35=C15, C15,"проверь!") -> 15000
A38: Решение №4: | B38: Распределить энергию на производство
A39: E24 | B39: Энергоресурсы для пр-ва продовольствия | C39: 8000
A40: E25 | B40: Энергоресурсы для пр-ва товаров | C40: 6600
A41: Всего: | B41: E24 + E25 = E23 | C41: =IF(C39+C40=C35, C35, "проверь!") -> 14600
A43: Решение №5: | B43: Капиталовложения в энергетику
A44: E26 | B44: Капиталовложения в генерацию энергии | C44: 500
A45: E27 | B45: Капиталовложения в энергосбережение | C45: 300
A51: Информация для разработчика | C51: п.п. | D51: прошлый период | G51: Индекс пред - переменная из предыдущего столбца (левее)
C52: т.п. | D52: текущий период | G52: Индекс тек - переменная из текущего столбца
...

Sheet Промышленность
C1: Факультет: | I1: Команда:
A4: Министр промышленности и сферы услуг (Goods) | C4: Лист решений
A6: Переменная | B6: Что описывает | C6: Старт. значение | D6: Периоды | M6: Целевое значение
C7: 0-4 | D7: 5-9 | E7: 10-14 | F7: 15-19 | G7: 20-24 | H7: 25-29 | I7: 30-34 | J7: 35-39 | K7: 40-44 | L7: 45-49
A8: Текущая ситуация
A9: G1 | B9: Выбытие капитала для пр-ва товаров (в конце периода) | C9: 60 | D9: =D11/5 -> 68 | M9: 900
A10: G2 | B10: Новый капитал для пр-ва товаров (т.п.) | C10: 240 | D10: =D11*4/5 -> 272 | M10: 3600
A11: G3 | B11: Основной капитал для пр-ва товаров (т.п.) | C11: =C9+C10 -> 300 | D11: =C11-C9+C30 -> 340 | M11: 4500
A12: G4 | B12: Выбытие капитала сферы услуг (в конце периода) | C12: 50 | D12: =D14/9 -> 88.888889 | M12: 1000
A13: G5 | B13: Новый капитал сферы услуг (т.п.) | C13: 400 | D13: =D14*8/9 -> 711.11111 | M13: 8000
A14: G6 | B14: Основной капитал сферы услуг (т.п.) | C14: =C12+C13 -> 450 | D14: =C14-C12+C31 -> 800 | M14: 9000
A16: Информация к сведению
A17: G7 | B17: Капитал на 1 рабочего (т.п.) | C17: 6 | D17: =D11/0.25/Население!D9 -> 6.1818182 | M17: 36
A18: G8 | B18: Коэф. пр-ти труда от акт. капитала на 1 рабочего (т.п.) | C18: 5 | D18: 6.22 | M18: 19.4
A19: G9 | B19: Услуги на душу населения (т.п.) | C19: 2.25 | D19: =D14/Население!D9 -> 3.6363636 | M19: 18
A20: G10 | B20: Коэф. пр-ти труда от услуг на душу населения (т.п.) | C20: 2.13 | D20: 2.81 | M20: 4.9
A21: G11 | B21: Коэффициент использования капитала (п.п.) | C21: 1 | D21: =IF(Энергетика!C40/Энергетика!C24>1.1,1.1,Энергетика!C40/Энергетика!C24) -> 1.1 | M21: 1
A22: G12 | B22: Фактическое производство товаров (п.п.) | C22: 3000 | D22: 5577 | M22: 68600
A23: G13 | B23: Экспорт товаров (п.п.) | C23: 0 | D23: ='Торговля и финансы'!C23 -> 0 | M23: 26000
A24: G14 | B24: Импорт товаров (п.п) | C24: 500 | D24: ='Торговля и финансы'!C35/'Торговля и финансы'!D17 -> 1181.8182 | M24: 0
A25: G15 | B25: Плановое производство товаров (т.п.) | C25: 3100 | D25: 5577 | M25: 68600
A26: G16 | B26: Всего товаров (п.п.) | C26: =C22+C24 -> 3500 | D26: =D22+D24 -> 6758.8182 | M26: 68600
A27: G17 | B27: Выбытие капитала во всех секторах эк-ки (к концу периода) | C27: 430 | D27: =Энергетика!D9+Энергетика!D12+Промышленность!D9+Промышленность!D12+'Сельхоз и ОС'!D9+'Сельхоз и ОС'!D12 -> 612.88889 | M27: 5110
A29: Решение №5: | B29: Распределить товары на капиталовложения
A30: G18 | B30: Капиталовложения в пр-во товаров | C30: 100
A31: G19 | B31: Капиталовложения в сферу услуг | C31: 400
D33: =D17*D21 -> 6.8
E34: =Население!D16/Население!C16*0.25*Население!D9*1.155*Промышленность!D20*Промышленность!D18*5 -> 5551.5133
A37: Информация для разработчика | C37: п.п. | D37: прошлый период | G37: Индекс пред - переменная из предыдущего столбца (левее)
C38: т.п. | D38: текущий период | G38: Индекс тек - переменная из текущего столбца
A39: Формулы и соотношения
A41: Переменная | B41: Что описывает | C41: Как рассчитывается | H41: Комментарий
A42: G1 | B42: Выбытие капитала для пр-ва товаров (в конце периода) | C42: = G3тек / 5 | H42: Сначала рассчитывается текущий основной капитал для пр-ва товаров G3. В конце периода 1/5 часть от него будет выбывать (срок жизни капитала 25 лет)
A43: G2 | B43: Новый капитал для пр-ва товаров (т.п.) | C43: = G3тек * 4 / 5 | H43: Сначала рассчитывается текущий основной капитал для пр-ва товаров G3. В конце периода от него останется 4/5 часть
A44: G3 | B44: Основной капитал для пр-ва товаров (т.п.) | C44: = G3пред - G1пред + G18пред = G2пред + G18пред | H44: Основной капитал для пр-ва товаров на текущий период рассчитывается как основной капитал G3 предыдущего периода за вычетом выбывающего капитала G1 + капиталовложения в пр-во товаров G18 по решению Министра пр-ти и сферы услуг
A45: G4 | B45: Выбытие капитала сферы услуг (в конце периода) | C45: = G6тек / 9 | H45: Сначала рассчитывается текущий основной капитал сферы услуг G6. В конце периода 1/9 часть от него будет выбывать (срок жизни капитала 45 лет)
A46: G5 | B46: Новый капитал сферы услуг (т.п.) | C46: = G6тек * 8 / 9 | H46: Сначала рассчитывается текущий основной капитал сферы услуг G6. В конце периода от него останется 8/9 часть
A47: G6 | B47: Основной капитал сферы услуг (т.п.) | C47: = G6пред - G4пред + G19пред = G5пред + G19пред | H47: Основной капитал сферы услуг на текущий период рассчитывается как основной капитал G6 предыдущего периода за вычетом выбывающего капитала G4 + капиталовложения в в сферу услуг G19 по решению Министра пр-ти и сферы услуг
A48: G7 | B48: Капитал на 1 рабочего (т.п.) | C48: = G3тек / (0,25 * P1тек) | H48: Отношение капитала для пр-ва товаров G3 к численности рабочей силы в пр-ти (рабочая сила = 0,25 * численность населения). Стартовое значение 6 уже рассчитано по этому соотношению
A49: G8 | B49: Коэф. пр-ти труда от акт. капитала на 1 рабочего (т.п.) | C49: = линейной интерполяцией по Графику G-3 как функция от значения (G7тек * G11тек) | H49: Пр-ть труда в промышленности зависит от отношения активного основного капитала для пр-ва товаров (основной капитал G3 * коэффициент использования капитала G11) к величине рабочей силы в промышленности (0,25 * P1). Стартовое значение 5 задано в явном виде. В английском оригинале коэффициент называется Multiplier of Goods Production (MGP)
...

Sheet Сельхоз и ОС
C1: Факультет: | I1: Команда:
A4: Министр сельского хозяйства и окружающей среды (Food) | C4: Лист решений
A6: Переменная | B6: Что описывает | C6: Старт. значение | D6: Периоды | M6: Целевое значение
C7: 0-4 | D7: 5-9 | E7: 10-14 | F7: 15-19 | G7: 20-24 | H7: 25-29 | I7: 30-34 | J7: 35-39 | K7: 40-44 | L7: 45-49
A8: Текущая ситуация
A9: F1 | B9: Выбытие с/х капитала (в конце периода) | C9: 160 | D9: =D11/5 -> 168 | M9: 500
A10: F2 | B10: Новый с/х капитал (т.п.) | C10: 640 | D10: =D11*4/5 -> 672 | M10: 2000
A11: F3 | B11: Основной с/х капитал (т.п.) | C11: =C9+C10 -> 800 | D11: =C11-C9+C26 -> 840 | M11: 2500
A12: F4 | B12: Выбытие природоохранного капитала (в конце периода) | C12: 0 | D12: =C14/6 -> 0 | M12: 6700
A13: F5 | B13: Новый природоохранный капитал (т.п.) | C13: 0 | D13: =C14*5/6 -> 0 | M13: 3300
A14: F6 | B14: Основной природоохранный капитал (т.п.) | C14: =C12+C13 -> 0 | D14: =C14-C12+C27 -> 0 | M14: 10000
A16: Информация к сведению
A17: F7 | B17: Состояние окружающей среды (т.п.) | C17: 0.69 | D17: =C17+3.6/100-3.8/100 -> 0.688 | M17: 0.8
A18: F8 | B18: Отношение капитала с/х к площади с/х угодий (т.п.) | C18: 0.8 | D18: =D11/1000 -> 0.84 | M18: 2.8
A19: F9 | B19: Плановое пр-во продовольствия (т.п.) | C19: 3450 | D19: 2890 | M19: 12500
A20: F10 | B20: Коэффициент использования с/х капитала (п.п.) | C20: 1 | D20: =IF(Энергетика!C39/Энергетика!C22>1.1,1.1,Энергетика!C39/Энергетика!C22) -> 0.8 | M20: 1
A21: F11 | B21: Производство продовольствия (п.п) | C21: 3300 | D21: 2890 | M21: 12500
A22: F12 | B22: Экспорт продовольствия (п.п.) | C22: 1550 | D22: ='Торговля и финансы'!C24 -> 1300 | M22: 0
A23: F13 | B23: Импорт продовольствия (п.п.) | C23: 0 | D23: ='Торговля и финансы'!C36/'Торговля и финансы'!D18 -> 0 | M23: 0
A25: Решение №5: | B25: Распределить капиталовложения
A26: F14 | B26: Капиталовложения в пр-во продовольствия | C26: 200
A27: F15 | B27: Капиталовложения в защиту окружающей среды | C27: 0
A33: Информация для разработчика | C33: п.п. | D33: прошлый период | G33: Индекс пред - переменная из предыдущего столбца (левее)
C34: т.п. | D34: текущий период | G34: Индекс тек - переменная из текущего столбца
A35: Формулы и соотношения
A37: Переменная | B37: Что описывает | C37: Как рассчитывается | H37: Комментарий
A38: F1 | B38: Выбытие с/х капитала (в конце периода) | C38: = F3тек / 5 | H38: Сначала рассчитывается текущий основной капитал для пр-ва продовольствия F3. В конце периода 1/5 часть от него будет выбывать (срок жизни капитала 25 лет)
A39: F2 | B39: Новый с/х капитал (т.п.) | C39: = F3тек * 4 / 5 | H39: Сначала рассчитывается текущий основной капитал для пр-ва продовольствия F3. В конце периода от него останется 4/5 часть
A40: F3 | B40: Основной с/х капитал (т.п.) | C40: = F3пред - F1пред + F14пред = F2пред + F14пред | H40: Основной капитал для пр-ва продовольствия на текущий период рассчитывается как основной капитал F3 предыдущего периода за вычетом выбывающего капитала F1 + капиталовложения в пр-во продовольствия F14 по решению Министра с/х и окружающей среды
A41: F4 | B41: Выбытие природоохранного капитала (в конце периода) | C41: = F6пред / 6 | H41: Сначала рассчитывается текущий основной природоохранный капитал F6. В конце периода 1/6 часть от него будет выбывать (срок жизни капитала 30 лет)
A42: F5 | B42: Новый природоохранный капитал (т.п.) | C42: = F6пред * 5 / 6 | H42: Сначала рассчитывается текущий основной природоохранный капитал F6. В конце периода от него останется 5/6 часть
A43: F6 | B43: Основной природоохранный капитал (т.п.) | C43: = F6пред - F4пред + F15пред = F5пред + F15пред | H43: Основной природоохранный капитал на текущий период рассчитывается как основной капитал F6 предыдущего периода за вычетом выбывающего капитала F4 + капиталовложения в защиту окружающей среды F15 по решению Министра с/х и окружающей среды
A44: F7 | B44: Состояние окружающей среды (т.п.) | C44: = F7пред + (линейной интерполяцией по графику F-4 как функция от F7пред) - (линейной интерполяцией по графику F-3 как функция от значения ((F3пред * F10пред + G3пред * G11пред + E3пред - 3 * F6пред) / 20000)) | H44: Текущее состояние ОС = предыдущее состояние ОС + восстановление - деградация. Восстановление зависит только от предыдущего состояния ОС по колокольному графику F-4. Деградация (рост загрязнения ОС за год в %) по графику F-3 зависит от некомпенсированного капитала в энергетике, некомпенсированного активного капитала в пр-ве продовольствия и товаров. 1 единица природоохранного капитала может компенсировать 3 единицы производящего капитала: капитала в энергетике, (капитала в пр-ве продовольствия * коэффициент исп-я капитала) и (капитала в пр-ве товаров * коэффициент исп-я капитала)
A45: F8 | B45: Отношение капитала с/х к площади с/х угодий (т.п.) | C45: = F3тек / 1000 | H45: Площадь с/х угодий постоянна и равна 1000 га. Стартовое значение уже рассчитано по указанной методике
A46: F9 | B46: Плановое пр-во продовольствия (т.п.) | C46: = 6250 * (линейной интерполяцией по графику F-2 как функция от значения (F3тек * F10тек / 1000)) * F7тек * 1 | H46: Производство продовольствия при 100%-ном обеспечении с/х энергоресурсами. Вместо коэффициента производительности труда от потребления продовольствия (который может быть меньше единицы, если уровень питания ухудшается) в формуле всегда берется 1 - в этом отличие планового производства продовольствия F9 от фактического F11
A47: F10 | B47: Коэффициент использования с/х капитала (п.п.) | C47: = E24пред / (E12пред) Если (E24пред / (E12пред)) > 1,1, то F10 = 1,1 | H47: Отношение энергоресурсов E24, выделенных для пр-ва продовольствия решением Министра энергетики, к потребности E12 в энергоресурсах для пр-ва продовольствия. Изменяется от 0 до 1,1. Энергоресурсы, выделенные сверх 110% от потребностей, теряются. Превышение потребностей в диапазоне ]100%;110%] увеличивает выпуск товаров пропорционально превышению. Стартовое значение 1 задано в явном виде, последующие рассчитываются через E24пред и E12пред
A48: F11 | B48: Фактическое производство продовольствия (т.п.) | C48: = 6250 * (линейной интерполяцией по графику F-2 как функция от значения (F3тек * F10тек / 1000)) * F7тек * (линейной интерполяцией по графику F-1 как функция от отношения (P4тек/P4пред) | H48: Коэффициент 6250 получен как произведение площади с/х угодий (1000), нормы урожайности (постоянная величина 1,25) на 5 лет. Далее умножение на коэффициент пр-ти труда в с/х от отношения активного с/х капитала к площади с/х угодий (по графику F-2, коэф. MFP (Multiplier of Food Production)), на состояние окружающей среды F7 и на коэффициент пр-ти труда в с/х от изменения уровня питания населения (по графику F-1, коэф. MFC (Multiplier of Food Consumption)). Коэффициентов в листах решений намеренно нет, их получают только по графикам. Стартовое значение 3300 задано в явном виде, последующие рассчитываются по формуле
... A50: F13 | B50: Импорт продовольствия (п.п.) | C50: = TF18пред / TF8тек | H50: Стартовое значение 500 задано в явном виде. В последующих периодах значение рассчитывается через валюту на импорт продовольствия TF18пред из графы "Решение №9" Министра внешней торговли и финансов, деленную на цену продовольствия TF8
A52: Проверка выполнения равенства при заполнении листа решений
C53: См. соответствие значений в листах решений разных министров
...

Sheet Торговля и финансы
C1: Факультет: | I1: Команда:
A4: Министр внешней торговли и финансов (Trade and Finance) | C4: Лист решений
A6: Переменная | B6: Что описывает | C6: Старт. значение | D6: Периоды
C7: 0-4 | D7: 5-9 | E7: 10-14 | F7: 15-19 | G7: 20-24 | H7: 25-29 | I7: 30-34 | J7: 35-39 | K7: 40-44 | L7: 45-49
A8: Информация к сведению
A9: TF1 | B9: Внешний долг (на начало периода) | C9: 0 | D9: =C9+C27+C14-C30 -> 1000
A11: Текущая ситуация
A12: TF2 | B12: Процентная ставка по кредиту (т.п.) | C12: 10 | D12: 10
A13: TF3 | B13: Коэффициент девальвации собственной валюты (т.п.) | C13: 1 | D13: 1
A14: TF4 | B14: Проценты за пользование кредитом (за п.п.) | C14: 0 | D14: =D9*D12/100*5 -> 500
A15: TF5 | B15: Максимально возможный кредит (т.п.) | C15: 1000 | D15: 1300
A16: TF6 | B16: Цена на импорт энергии | C16: 1 | D16: =D13*1 -> 1
A17: TF7 | B17: Цена на импорт товаров | C17: 1.1 | D17: =D13*1.1 -> 1.1
A18: TF8 | B18: Цена на импорт продовольствия | C18: 1.1 | D18: =D13*1.1 -> 1.1
A20: Решение №:6 | B20: Оценить поступление валюты по статьям
A21: TF9 | B21: Иностранная помощь | C21: 0
A22: TF10 | B22: Энергия на экспорт | C22: 0
A23: TF11 | B23: Товары на экспорт | C23: 0
A24: TF12 | B24: Продовольствие на экспорт | C24: 1300
A26: Решение №7: | B26: Принять решение о новом иностранном займе
A27: TF13 | B27: Новый кредит | C27: 1000
A29: Решение №8: | B29: Принять решение о выплатах по долгу
A30: TF14 | B30: Выплаты по долгу (т.п.) | C30: 0
A32: Решение №9: | B32: Распределить валюту на закупки по импорту
A33: TF15 | B33: Валюта для импорта, суммарно | C33: 2300
A34: TF16 | B34: Валюта для импорта энергии | C34: 1000
A35: TF17 | B35: Валюта для импорта товаров | C35: 1300
A36: TF18 | B36: Валюта для импорта продовольствия | C36: 0
A37: Всего: | B37: TF16 + TF17 + TF18 = TF15 | C37: =IF(C34+C35+C36=C33, C33, "проверь!") -> 2300
B38: TF9 + TF10 + TF11 + TF12 + TF13 - TF14 = TF15 | C38: =IF(C21+C22+C23+C24+C27-C30=C33,C33,"проверь!") -> 2300
A41: Информация для разработчика | C41: п.п. | D41: прошлый период | G41: Индекс пред - переменная из предыдущего столбца (левее)
C42: т.п. | D42: текущий период | G42: Индекс тек - переменная из текущего столбца
A43: Формулы и соотношения
A45: Переменная | B45: Что описывает | C45: Как рассчитывается | H45: Комментарий
A46: TF1 | B46: Внешний долг (на начало периода) | C46: = TF1пред + TF13пред + TF4пред - TF14пред | H46: Величина внешнего долга рассчитывается как долг прошлого периода TF1пред + новый кредит TF13 из графы "Решение №7" Министра внешней торговли и финансов + проценты за пользование кредитом TF4 минус долговые выплаты текущего периода TF14 из графы "Решение №8" Министра внешней торговли и финансов
A47: TF2 | B47: Процентная ставка по кредиту (т.п.) | C47: = линейной интерполяцией по графику TF-2 как функция от отношения (TF1тек / ([TF10 + TF11 + TF12]средн.за3периода)) | H47: Стартовое значение 10% в год (50% за период), затем рассчитывается по графику TF-2. Суммарный экспорт энергии, товаров и продовольствия усредняется за три предыдущих периода. Если долг в 5 раз превысит средний суммарный объем экспорта, ставка составит 20%
A48: TF3 | B48: Коэффициент девальвации собственной валюты (т.п.) | C48: = линейной интерполяцией по графику TF-1 как функция от отношения (TF1тек / ([TF10 + TF11 + TF12]средн.за3периода)) | H48: Стартовое значение 1. Если долг в 5 раз превысит средний суммарный объем экспорта, коэффициент девальвации возрастет до 2. На коэффициент девальвации умножаются цены за импортируемые энергию, продовольствие и товары
A49: TF4 | B49: Выплаты по процентам (п.п.) | C49: = TF1тек * (TF2тек / 100) * 5 | H49: Рассчитываются как величина долга, умноженная на процентную ставку/100 и умноженная на 5 лет
A50: TF5 | B50: Максимально возможный заём (т.п.) | C50: = 0, если TF1тек ≥ ([TF10 + TF11 + TF12]средн.за3периода) = [TF10 + TF11 + TF12]средн.за3периода, если эта величина больше внешнего долга | H50: Стартовое значение 1000, для последующих периодов расчет по формуле
A51: TF6 | B51: Цена на импорт энергии | C51: = 1 * TF3тек | H51: Максимальное подорожание в сравнении со стартовым значением 1 - в 2 раза, до 2 за единицу энергии
...

Sheet Сводный лист решений
D1: Факультет: | J1: Команда:
D4: Сводный лист решений
B6: Переменная | C6: Что описывает | D6: Старт. значение | E6: Периоды
D7: 0-4 | E7: 5-9 | F7: 10-14 | G7: 15-19 | H7: 20-24 | I7: 25-29 | J7: 30-34 | K7: 35-39 | L7: 40-44 | M7: 45-49
A8: №1 | B8: P9 | C8: Продовольствие для населения (т.п.)
B9: P10 | C9: Продовольствие на экспорт (т.п.)
B10: Всего: | C10: P9 + P10 = P2
A11: №2 | B11: P11 | C11: Товары для населения (т.п.)
B12: P12 | C12: Товары для капиталовложения (т.п.)
B13: P13 | C13: Товары на экспорт (т.п.)
B14: Всего: | C14: P11 + P12 + P13 = P3
A15: №3 | B15: E20 | C15: Энергоресурсы для населения (1/5 потребл. товаров)
B16: E21 | C16: Энергоресурсы на экспорт
B17: E22 | C17: Энергоресурсы в резерв
B18: E23 | C18: Энергоресурсы для пр-ва товаров и продовольствия
B19: Всего: | C19: E20 + E21 + E22 + E23 = E7
A20: №4 | B20: E24 | C20: Энергоресурсы для пр-ва продовольствия
B21: E25 | C21: Энергоресурсы для пр-ва товаров
B22: Всего: | C22: E24 + E25 = E23
A23: №5 | B23: E26 | C23: Капиталовложения в генерацию энергии
B24: E27 | C24: Капиталовложения в энергосбережение
B25: G18 | C25: Капиталовложения в пр-во товаров
B26: G19 | C26: Капиталовложения в сферу услуг
B27: F14 | C27: Капиталовложения в пр-во продовольствия
B28: F15 | C28: Капиталовложения в защиту окружающей среды
B29: Всего: | C29: E26 + E27 + G18 + G19 + F14 + F15 = P12
A30: №6 | B30: TF9 | C30: Иностранная помощь
B31: TF10 | C31: Энергия на экспорт
B32: TF11 | C32: Товары на экспорт
B33: TF12 | C33: Продовольствие на экспорт
A34: №7 | B34: TF13 | C34: Новый кредит (TF13 <= TF5)
A35: №8 | B35: TF14 | C35: Выплаты по долгу (т.п.)
A36: №9 | B36: TF15 | C36: Валюта для импорта, суммарно (TF9 + TF10 + TF11 + TF12 + TF13 - TF14)
B37: TF16 | C37: Валюта для импорта энергии
B38: TF17 | C38: Валюта для импорта товаров
B39: TF18 | C39: Валюта для импорта продовольствия
B40: Всего: | C40: TF16 + TF17 + TF18 = TF5
B44: Информация для разработчика | D44: п.п. | E44: прошлый период | H44: Индекс пред - переменная из предыдущего столбца (левее)
D45: т.п. | E45: текущий период | H45: Индекс тек - переменная из текущего столбца

Sheet Лист состояния страны
C1: Факультет: | I1: Команда:
C4: Лист состояния страны
A6: Переменная | B6: Что описывает | C6: Старт. значение | D6: Периоды
C7: 0-4 | D7: 5-9 | E7: 10-14 | F7: 15-19 | G7: 20-24 | H7: 25-29 | I7: 30-34 | J7: 35-39 | K7: 40-44 | L7: 45-49
A8: P1 | B8: Численность населения (округляется до десятков) | C8: 200 | D8: 220
A9: P4 | B9: Продовольствие на душу населения в год | C9: 2 | D9: 2
A10: P6 | B10: Товары на душу населения в год | C10: 2 | D10: 2
A11: = P6 + 4 * P4 | B11: Сводный счет (усредняется за все прошедшие периоды игры) | C11: =C10+4*C9 -> 10 | D11: =D10+4*D9 -> 10
A12: P5 | B12: Уровень смертности, чел./1000 чел. в год | C12: 18 | D12: 18.2
A13: P8 | B13: Уровень рождаемости, чел./1000 чел. в год | C13: 41 | D13: 39.2
A14: = (P8 - P5) / 1000 | B14: Темпы роста численности населения (годовой прирост населения в процентах) | C14: =(C13-C12)/1000 -> 0.023 | D14: =(D13-D12)/1000 -> 0.021
A15: TF1 | B15: Внешний долг | C15: 0 | D15: 1000
A16: F7 | B16: Состояние окружающей среды | C16: 0.69 | D16: 0.688
A17: E10 | B17: Коэффициент потребления энергоресурсов | C17: 1 | D17: 0.64
A18: F3 | B18: Основной с/х капитал | C18: 800 | D18: 840
A19: F9 | B19: Плановое пр-во продовольствия | C19: 3450 | D19: 2890
A20: = F9 / F3 | B20: Эффективность сельского хозяйства (продовольствие на единицу капитала в с/х) (округляется до целых, со временем сокращается) | C20: =C19/C18 -> 4.3125 | D20: =D19/D18 -> 3.4404762
A21: G3 | B21: Основной капитал для пр-ва товаров | C21: 300 | D21: 340
A22: G6 | B22: Основной капитал сферы услуг | C22: 450 | D22: 800
A23: G15 | B23: Плановое производство товаров | C23: 3100 | D23: 5577
A24: = G15 / (G3 + G6) | B24: Эффективность промышленности (товаров на единицу капитала в промышленности и сфере услуг) (округляется до целых, со временем сокращается) | C24: =ROUND(C23/(C21+C22),0) -> 4 | D24: =ROUND(D23/(D21+D22),0) -> 5
A25: E16 | B25: Эффективность энергетики (генерация энергии на единицу капитала в энергетике) (округляется до целых, со временем сокращается) | C25: =ROUND(17.5,0) -> 18 | D25: =ROUND(15.6578947368421,0) -> 16
A26: P2 | B26: Всего продовольствия от импорта и пр-ва | C26: 3300 | D26: 2890
A27: P3 | B27: Всего товаров от импорта и пр-ва | C27: 3500 | D27: 6758.8182
A28: E7 | B28: Всего энергоресурсов от пр-ва, импорта и резерва | C28: 15000 | D28: 18850

Sheet График P-1
A1: Figure P-1: Normal birth rate as a function of average good consumption per year per person (averaged over the last three cycles). | C1: Ось
A2: График P-1. Зависимость коэффициента рождаемости от среднего потребления товаров на душу населения в год за прошлые три периода. | C2: X | D2: 0 | E2: 1.5 | F2: 3 | G2: 4.5 | H2: 6 | I2: 7.5 | J2: 9 | K2: 10.5 | L2: 12 | M2: 13.5 | N2: 15
C3: Y | D3: 0.03 | E3: 0.028 | F3: 0.026 | G3: 0.024 | H3: 0.022 | I3: 0.019 | J3: 0.016 | K3: 0.013 | L3: 0.011 | M3: 0.01 | N3: 0.01
A5: X
A6: Среднее потребление товаров на душу населения в год за прошлые три периода
A8: Y
A9: Коэффициент рождаемости
A10: (если переводить размерность коэффициента в промилле (чел./1000 чел.), то величины нужно умножить на 1000)
C23: Интерполяция
C24: X | D24: 1.5 | E24: 3 | F24: 2
C25: Y | D25: 0.028 | E25: 0.026 | F25: =IF(AND(F24>=D24, F24<=E24), ((F24-D24)/(E24-D24)*(E25-D25)+D25), "неверный диапазон") -> 0.027333333

Sheet График P-2
A1: Figure P-2: Birth multiplier as a function of human services capital per person. | C1: Ось
A2: График P-2. Зависимость множителя рождаемости от услуг на душу населения. | C2: X | D2: 0 | E2: 2 | F2: 4 | G2: 6 | H2: 8 | I2: 10 | J2: 12 | K2: 14 | L2: 16 | M2: 18 | N2: 20
C3: Y | D3: 1 | E3: 1.5 | F3: 1.45 | G3: 1.4 | H3: 1.35 | I3: 1.3 | J3: 1.2 | K3: 1.1 | L3: 1 | M3: 1 | N3: 1
A5: X
A6: Капитал сферы услуг на душу населения
A8: Y
A9: Множитель рождаемости
A10: (безразмерен)
C23: Интерполяция
C24: X | D24: 0 | E24: 2 | F24: 1
C25: Y | D25: 1 | E25: 1.5 | F25: =IF(AND(F24>=D24, F24<=E24), ((F24-D24)/(E24-D24)*(E25-D25)+D25), "неверный диапазон") -> 1.25

Sheet График P-3
A1: Figure P-3: Normal death rate as a function of food consumption per year per person. | C1: Ось
A2: График P-3. Зависимость уровня смертности от продовольствия на душу населения в год. | C2: X | D2: 0 | E2: 0.5 | F2: 1 | G2: 1.5 | H2: 2 | I2: 2.5 | J2: 3 | K2: 3.5 | L2: 4 | M2: 4.5 | N2: 5
C3: Y | D3: 0.06 | E3: 0.045 | F3: 0.03 | G3: 0.022 | H3: 0.018 | I3: 0.015 | J3: 0.013 | K3: 0.012 | L3: 0.011 | M3: 0.01 | N3: 0.01
A5: X
A6: Продовольствие на душу населения в год
A8: Y
A9: Коэффициент смертности
A10: (если переводить размерность коэффициента в промилле (чел./1000 чел.), то величины нужно умножить на 1000)
C24: Интерполяция
C25: X | D25: 0 | E25: 0.5 | F25: 0.25
C26: Y | D26: 0.06 | E26: 0.045 | F26: =IF(AND(F25>=D25, F25<=E25), ((F25-D25)/(E25-D25)*(E26-D26)+D26), "неверный диапазон") -> 0.0525

Sheet График P-4
A1: Figure P-4: Death multiplier as a function of the quality of the environment. | C1: Ось
A2: График P-4. Зависимость множителя смертности от состояния окружающей среды. | C2: X | D2: 0 | E2: 0.1 | F2: 0.2 | G2: 0.3 | H2: 0.4 | I2: 0.5 | J2: 0.6 | K2: 0.7 | L2: 0.8 | M2: 0.9 | N2: 1
C3: Y | D3: 1.75 | E3: 1.6 | F3: 1.5 | G3: 1.4 | H3: 1.3 | I3: 1.2 | J3: 1.1 | K3: 1 | L3: 1 | M3: 1 | N3: 1
A5: X
A6: Состояние окружающей среды
A8: Y
A9: Множитель смертности
A10: (безразмерен)
C24: Интерполяция
C25: X | D25: 0.6 | E25: 0.7 | F25: 0.688
C26: Y | D26: 1.1 | E26: 1 | F26: =IF(AND(F25>=D25, F25<=E25), ((F25-D25)/(E25-D25)*(E26-D26)+D26), "неверный диапазон") -> 1.012

Sheet График E-1
A1: Figure E-1: Energy production per cycle as a function of energy production capital (both in units of 1000's). | C1: Ось
A2: График E-1. Зависимость генерации энергоресурсов за период от капитала для пр-ва энергии (размерности по осям в 1000 единиц). | C2: X | D2: 0 | E2: 1 | F2: 2 | G2: 3 | H2: 4 | I2: 5 | J2: 6 | K2: 7 | L2: 8 | M2: 9 | N2: 10
C3: Y | D3: 0.03 | E3: 17.5 | F3: 20 | G3: 22.5 | H3: 25 | I3: 27.5 | J3: 30 | K3: 32 | L3: 33.5 | M3: 34.5 | N3: 35
A5: X
A6: Капитал для пр-ва энергии
A7: (размерность в 1000 единиц)
A9: Y
A10: Генерация энергоресурсов за период
A11: (размерность в 1000 единиц)
D23: Y/X | E23: =E3/E2 -> 17.5 | F23: =F3/F2 -> 10 | G23: =G3/G2 -> 7.5 | H23: =H3/H2 -> 6.25 | I23: =I3/I2 -> 5.5 | J23: =J3/J2 -> 5 | K23: =K3/K2 -> 4.5714286 | L23: =L3/L2 -> 4.1875 | ... N23: =N3/N2 -> 3.5
C25: Интерполяция
C26: X | D26: 0 | E26: 1 | F26: =1140/1000 -> 1.14
C27: Y | D27: 0.03 | E27: 17.5 | F27: =IF(AND(F26>=D26, F26<=E26), ((F26-D26)/(E26-D26)*(E27-D27)+D27), "неверный диапазон") -> неверный диапазон

Sheet График E-2
A1: Figure E-2: Energy consumption multiplier as a function of energy efficiency capital per unit of total capital in food and goods production. | C1: Ось
A2: График E-2. Зависимость коэффициента потребления ресурсов от капиталовложений в энергосбережение. | C2: X | D2: 0 | E2: 0.1 | F2: 0.2 | G2: 0.3 | H2: 0.4 | I2: 0.5 | J2: 0.6 | K2: 0.7 | L2: 0.8 | M2: 0.9 | N2: 1
C3: Y | D3: 1 | E3: 0.8 | F3: 0.7 | G3: 0.58 | H3: 0.5 | I3: 0.42 | J3: 0.4 | K3: 0.35 | L3: 0.33 | M3: 0.31 | N3: 0.3
A5: X
A6: Капиталовложения в энергосбережения
A8: Y
A9: Коэффициент потребления ресурсов
A10: (безразмерен)
C23: Интерполяция
C24: X | D24: 0.2 | E24: 0.3 | F24: 0.254
C25: Y | D25: 0.7 | E25: 0.58 | F25: =IF(AND(F24>=D24, F24<=E24), ((F24-D24)/(E24-D24)*(E25-D25)+D25), "неверный диапазон") -> 0.6352

Sheet График G-1
A1: Figure G-1: Multiplier on goods production as a function of the ratio of goods consumption this cycle to the consumption last cycle (MGC). | C1: Ось
A2: График G-1. Зависимость коэффициента производительности труда от изменения материального уровня жизни. | C2: X | D2: 0 | E2: 0.2 | F2: 0.4 | G2: 0.6 | H2: 0.8 | I2: 1 | J2: 1.2 | K2: 1.4 | L2: 1.6 | M2: 1.8 | N2: 2
C3: Y | D3: 0.4 | E3: 0.52 | F3: 0.64 | G3: 0.76 | H3: 0.88 | I3: 1 | J3: 1 | K3: 1 | L3: 1 | M3: 1 | N3: 1
A5: X
A6: Отношение потребления товаров на душу наслеения в текущем периоде к прошлому периоду
A8: Y
A9: Коэффициент производительности труда от изменения в уровне потребления
A10: (безразмерен)
C23: Интерполяция
C24: X | D24: 0 | E24: 0.2 | F24: 0.1
C25: Y | D25: 0.4 | E25: 0.52 | F25: =IF(AND(F24>=D24, F24<=E24), ((F24-D24)/(E24-D24)*(E25-D25)+D25), "неверный диапазон") -> 0.46

Sheet График G-2
A1: Figure G-2: Multiplier on goods production as a function of the ratio of human services capital to the total population (MHS). | C1: Ось
A2: График G-2. Зависимость коэффициента производительности труда от капитала сферы услуг на душу населения. | C2: X | D2: 0 | E2: 2 | F2: 4 | G2: 6 | H2: 8 | I2: 10 | J2: 12 | K2: 14 | L2: 16 | M2: 18 | N2: 20
C3: Y | D3: 1 | E3: 2 | F3: 3 | G3: 3.5 | H3: 4 | I3: 4.3 | J3: 4.5 | K3: 4.7 | L3: 4.8 | M3: 4.9 | N3: 5
A5: X
A6: Капитал сферы услуг на душу населения
A8: Y
A9: Коэффициент производительности труда от услуг на душу населения
A10: (безразмерен)
C23: Интерполяция
C24: X | D24: 2 | E24: 4 | F24: 3.62
C25: Y | D25: 2 | E25: 3 | F25: =IF(AND(F24>=D24, F24<=E24), ((F24-D24)/(E24-D24)*(E25-D25)+D25), "неверный диапазон") -> 2.81

Sheet График G-3
A1: Figure G-3: Multiplier on goods production as a function of the active goods production capital per labourer (MGP). | C1: Ось
A2: График G-3. Зависимость коэффициента производительности труда от величины активного производительного капитала на 1 рабочего. | C2: X | D2: 0 | E2: 4 | F2: 8 | G2: 12 | H2: 16 | I2: 20 | J2: 24 | K2: 28 | L2: 32 | M2: 36 | N2: 40
C3: Y | D3: 0.8 | E3: 4 | F3: 7.2 | G3: 10.4 | H3: 12.5 | I3: 14.4 | J3: 16 | K3: 17.2 | L3: 18.5 | M3: 19.4 | N3: 20
A5: X
A6: Величина активного производительного капитала на 1 рабочего
A8: Y
A9: Коэффициент производительности труда от капитала на 1 рабочего
A10: (безразмерен)
C23: Интерполяция
C24: X | D24: 4 | E24: 8 | F24: 6.77
C25: Y | D25: 4 | E25: 7.2 | F25: =IF(AND(F24>=D24, F24<=E24), ((F24-D24)/(E24-D24)*(E25-D25)+D25), "неверный диапазон") -> 6.216

Sheet График F-1
A1: Figure F-1: Multiplier on food production as a function of the ratio of food consumption this cycle to the last cycle (MFC). | C1: Ось
A2: График F-1. Зависимость коэффициента пр-ти труда в с/х от изменения уровня питания населения. | C2: X | D2: 0 | E2: 0.2 | F2: 0.4 | G2: 0.6 | H2: 0.8 | I2: 1 | J2: 1.2 | K2: 1.4 | L2: 1.6 | M2: 1.8 | N2: 2
C3: Y | D3: 0.4 | E3: 0.52 | F3: 0.64 | G3: 0.76 | H3: 0.88 | I3: 1 | J3: 1 | K3: 1 | L3: 1 | M3: 1 | N3: 1
A5: X
A6: Отношение потребления продовольствия на душу населения в текущем периоде к прошлому периоду
A8: Y
A9: Коэффициент производительности труда в с/х от изменения в уровне питания
A10: (безразмерен)
C23: Интерполяция
C24: X | D24: 0.8 | E24: 1 | F24: 1
C25: Y | D25: 0.88 | E25: 1 | F25: =IF(AND(F24>=D24, F24<=E24), ((F24-D24)/(E24-D24)*(E25-D25)+D25), "неверный диапазон") -> 1

Sheet График F-2
A1: Figure F-2: Multiplier on food production as a function of the active food production capital per unit of area (MFP). | C1: Ось
A2: График F-2. Зависимость коэффициента пр-ти труда в с/х от отношения активного с/х капитала к площади с/х угодий. | C2: X | D2: 0 | E2: 1 | F2: 2 | G2: 3 | H2: 4 | I2: 5 | J2: 6 | K2: 7 | L2: 8 | M2: 9 | N2: 10
C3: Y | D3: 0 | E3: 1 | F3: 2 | G3: 3 | H3: 3.7 | I3: 4.2 | J3: 4.5 | K3: 4.7 | L3: 4.8 | M3: 4.9 | N3: 5
A5: X
A6: Отношение активного с/х капитала к площади с/х угодий
A8: Y
A9: Коэффициент производительности труда в с/х от активного с/х капитала на единицу площади угодий
A10: (безразмерен)
C23: Интерполяция
C24: X | D24: 0 | E24: 1 | F24: 0.462
C25: Y | D25: 0 | E25: 1 | F25: =IF(AND(F24>=D24, F24<=E24), ((F24-D24)/(E24-D24)*(E25-D25)+D25), "неверный диапазон") -> 0.462

Sheet График F-3
A1: Figure F-3: Annual percentage of environmental degeneration as a function of the sum of differences of active capital (E, F, G) and environmental protection capital, scaled to 20000. | C1: Ось
A2: График F-3. Увеличение загрязнения окружающей среды за год в % в зависимости от суммарного некомпенсированного капитала в энергетике, пр-ве продовольствия и товаров. | C2: X | D2: 0 | E2: 0.1 | F2: 0.2 | G2: 0.3 | H2: 0.4 | I2: 0.5 | J2: 0.6 | K2: 0.7 | L2: 0.8 | M2: 0.9 | N2: 1
C3: Y | D3: 0 | E3: 4 | F3: 5.5 | G3: 7 | H3: 7.8 | I3: 8.3 | J3: 9 | K3: 9.3 | L3: 9.5 | M3: 9.7 | N3: 10
A5: X
A6: Суммарный некомпенсированный капитал в энергетике, пр-ве товаров и продовольствия / 20 000
A8: Y
A9: Увеличение загрязнения окружающей среды за год в %
C23: Интерполяция
C24: X | D24: 0 | E24: 0.1 | F24: 0.095
C25: Y | D25: 0 | E25: 4 | F25: =IF(AND(F24>=D24, F24<=E24), ((F24-D24)/(E24-D24)*(E25-D25)+D25), "неверный диапазон") -> 3.8

Sheet График F-4
A1: Figure F-4: Annual percentage of environmental regeneration capacity as a function of the quality of the environment. | C1: Ось
A2: График F-1. Способность окружающей среды к самовосстановлению в зависимости от ее текущего состояния. | C2: X | D2: 0 | E2: 0.1 | F2: 0.2 | G2: 0.3 | H2: 0.4 | I2: 0.5 | J2: 0.6 | K2: 0.7 | L2: 0.8 | M2: 0.9 | N2: 1
C3: Y | D3: 0.03 | E3: 0.2 | F3: 2 | G3: 3.5 | H3: 4.5 | I3: 5 | J3: 4.5 | K3: 3.5 | L3: 2 | M3: 0.2 | N3: 0.01
A5: X
A6: Состояние окружающей среды
A7: (безразмерная величина)
A9: Y
A10: Восстановление окружающей среды за год в %
C24: Интерполяция
C25: X | D25: 0.6 | E25: 0.7 | F25: 0.69
C26: Y | D26: 4.5 | E26: 3.5 | F26: =IF(AND(F25>=D25, F25<=E25), ((F25-D25)/(E25-D25)*(E26-D26)+D26), "неверный диапазон") -> 3.6

Sheet График TF-1
A1: Figure TF-1:Multiplier on import prices as a function of the ratio of debt to the average exports. | C1: Ось
A2: График TF-1. Зависимость коэффициента девальвации собственной валюты от отношения внешнего долга к величине экспорта, усредненной за прошлые три периода. | C2: X | D2: 0 | E2: 0.5 | F2: 1 | G2: 1.5 | H2: 2 | I2: 2.5 | J2: 3 | K2: 3.5 | L2: 4 | M2: 4.5 | N2: 5
C3: Y | D3: 1 | E3: 1 | F3: 1 | G3: 1 | H3: 1 | I3: 1 | J3: 1.2 | K3: 1.4 | L3: 1.6 | M3: 1.8 | N3: 2
A5: X
A6: Отношение внешнего долга к средней величине экспорта за прошлые три периода
A8: Y
A9: Коэффициент девальвации собственной валюты
A10: (безразмерен)
C23: Интерполяция
C24: X | D24: 0 | E24: 0.5 | F24: 0.5
C25: Y | D25: 1 | E25: 1 | F25: =IF(AND(F24>=D24, F24<=E24), ((F24-D24)/(E24-D24)*(E25-D25)+D25), "неверный диапазон") -> 1

Sheet График TF-2
A1: Figure TF-2: Interest rate as a function of the ratio of debt to the average export. | C1: Ось
A2: График TF-2. Зависимость процентной ставки по кредиту от отношения внешнего долга к величине экспорта, усредненной за прошлые три периода. | C2: X | D2: 0 | E2: 0.5 | F2: 1 | G2: 1.5 | H2: 2 | I2: 2.5 | J2: 3 | K2: 3.5 | L2: 4 | M2: 4.5 | N2: 5
C3: Y | D3: 10 | E3: 10 | F3: 10 | G3: 12 | H3: 14 | I3: 15 | J3: 16 | K3: 17 | L3: 18 | M3: 19 | N3: 20
A5: X
A6: Отношение внешнего долга к средней величине экспорта за прошлые три периода
A8: Y
A9: Ставка по кредиту, %
C23: Интерполяция
C24: X | D24: 0.5 | E24: 1 | F24: 0.77
C25: Y | D25: 10 | E25: 10 | F25: =IF(AND(F24>=D24, F24<=E24), ((F24-D24)/(E24-D24)*(E25-D25)+D25), "неверный диапазон") -> 10
